#VRML_SIM R2023b utf8

IMPORTABLE EXTERNPROTO "../protos/RoboCupBackground.proto"
IMPORTABLE EXTERNPROTO "../protos/RobocupSoccerField.proto"
IMPORTABLE EXTERNPROTO "../protos/lighting/RoboCupMainLight.proto"
IMPORTABLE EXTERNPROTO "../protos/lighting/RoboCupOffLight.proto"
IMPORTABLE EXTERNPROTO "../protos/lighting/RoboCupTopLight.proto"
EXTERNPROTO "https://raw.githubusercontent.com/cyberbotics/webots/R2023b/projects/objects/balls/protos/Ball.proto"

WorldInfo {
  info [
    "Description: official soccer simulation for the 2021 Robocup Virtual Humanoid League (kid size)"
    "Version 0.3"
  ]
  title "Robocup V-HL Kid"
  basicTimeStep 8
  physicsDisableTime 0.1
  physicsDisableLinearThreshold 0.1
  physicsDisableAngularThreshold 0.1
  contactProperties [
    ContactProperties {
      material1 "grass"
      coulombFriction [
        0.5
      ]
      softCFM 0.03
    }
    ContactProperties {
      material1 "grass"
      material2 "robocup soccer ball"
      coulombFriction [
        0.5
      ]
      bounce 0.76
      softCFM 0.05
    }
    ContactProperties {
      material2 "robocup soccer ball"
      bounce 0.76
    }
  ]
}
Viewpoint {
  orientation 0.12211981817279666 -0.6893141129274506 -0.7140957945041301 5.796811976129791
  position -8.386143190842644 -3.9342141326442763 2.9062424720088744
}
RobocupSoccerField {
  size "kid"
}
RoboCupMainLight {
}
RoboCupOffLight {
}
RoboCupTopLight {
}
RoboCupBackground {
}
Ball {
  translation -3.09 -1.84 0.08935253999999997
  radius 0.08
}
Robot {
  translation -1.5077095458635714 -1.4978831222313567 0.3945570190710062
  rotation 0.0028498756234595986 -0.9192939253866816 0.3935613763519955 0.02759485997258096
  children [
    Solid {
      rotation 0 0 1 1.5708
      children [
        SAHRV74_trunk_1Mesh {
        }
        DEF head_yaw HingeJoint {
          jointParameters HingeJointParameters {
            position 15.457656006647895
            axis 0 0 -1
            anchor 0.050658 -0.011338 0.184196
            dampingConstant 0.65
            staticFriction 1.73
          }
          device [
            PositionSensor {
              name "head_yaw_sensor"
              resolution 0.0015
            }
            RotationalMotor {
              name "head_yaw"
              maxVelocity 8.17
              maxTorque 7.3
            }
          ]
          endPoint Solid {
            translation 0.050658 -0.011338 0.184196
            rotation 0 0 -0.9999999999999999 2.891285392288722
            children [
              SAHRV74_u_neck_1Mesh {
              }
              DEF head_pitch HingeJoint {
                jointParameters HingeJointParameters {
                  position 0.3255000882897512
                  axis 0.999884 -0.015247 0
                  anchor 0 7.9e-05 0.035704
                  dampingConstant 0.65
                  staticFriction 1.73
                }
                device [
                  RotationalMotor {
                    name "head_pitch"
                    maxVelocity 8.17
                    maxTorque 7.3
                  }
                  PositionSensor {
                    name "head_pitch_sensor"
                    resolution 0.0015
                  }
                ]
                endPoint Solid {
                  translation 0 7.9e-05 0.035704
                  rotation -0.5028092667841391 0.7009410121323619 -0.5058305435092432 1.9148320306584694
                  children [
                    SAHRV74_head_1Mesh {
                    }
                    Solid {
                      translation -0.013333 -0.0476 -0.017
                      rotation 0.7071072811865696 0 0.7071062811861719 3.141593
                      children [
                        SAHRV74_Head_UpMesh {
                        }
                      ]
                      name "Head_Up"
                      boundingObject Pose {
                        translation 0.017 0.02149 0.011412
                        rotation 0 1 0 0
                        children [
                          Box {
                            size 0.113972 0.05378 0.09
                          }
                        ]
                      }
                      physics Physics {
                        density -1
                        mass 0.300905
                        centerOfMass [
                          0.017038 0.020221 0.017863
                        ]
                        inertiaMatrix [
                          0.000101409 0.0002061129 0.0001574972
                          -9.314016e-08 2.12664e-07 7.67536e-06
                        ]
                      }
                    }
                    Camera {
                      translation 0.037313 -0.07 0.031
                      rotation 0.9999996825744581 0.0005634052638516527 0.0005634052638515914 1.5696704679478388
                      children [
                        DEF camera_left Solid {
                          rotation 0.5773502691896258 -0.5773502691896258 -0.5773502691896258 2.0943951023931957
                          children [
                            SAHRV74_camera_leftMesh {
                            }
                          ]
                          name "camera_left"
                        }
                      ]
                      name "left_camera"
                      fieldOfView 1.762
                      width 1440
                      height 1080
                      lens Lens {
                        radialCoefficients -0.26 -0.26
                      }
                    }
                    Camera {
                      translation 0.037312 -0.07 -0.031
                      rotation 0.9999996825744581 0.0005634052638516527 0.0005634052638515914 1.5696704679478388
                      children [
                        DEF camera_right Solid {
                          rotation 0.5773502691896258 -0.5773502691896258 -0.5773502691896258 2.0943951023931957
                          children [
                            SAHRV74_camera_rightMesh {
                            }
                          ]
                          name "camera_right"
                        }
                      ]
                      name "right_camera"
                      fieldOfView 1.762
                      width 720
                      height 540
                      lens Lens {
                        radialCoefficients -0.26 -0.26
                      }
                    }
                  ]
                  name "head_1"
                  boundingObject Pose {
                    translation 7.9e-05 -0.01655 0
                    rotation 0 1 0 0
                    children [
                      Box {
                        size 0.0402 0.0621 0.047
                      }
                    ]
                  }
                  physics Physics {
                    density -1
                    mass 0.14393
                    centerOfMass [
                      7.9e-05 -0.01434 -0.000287
                    ]
                    inertiaMatrix [
                      5.757008e-05 3.270303e-05 4.850776e-05
                      2.266866e-11 -3.266193e-11 -1.641461e-06
                    ]
                  }
                }
              }
              Solid {
                translation -0.0265 0.0001 0.035204
                rotation 0.5773502691896258 0.5773502691896258 -0.5773502691896258 2.094395
                children [
                  SAHRV74_u_neck_bone_rightMesh {
                  }
                ]
                name "u_neck_bone_right"
                boundingObject Pose {
                  translation 0.009875 0.0015 0.0001
                  rotation 0 1 0 0
                  children [
                    Box {
                      size 0.04085 0.003 0.03
                    }
                  ]
                }
                physics Physics {
                  density -1
                  mass 0.004792
                  centerOfMass [
                    0.012953 0.0015 0.0001
                  ]
                  inertiaMatrix [
                    3.650961e-07 9.043631e-07 5.464543e-07
                    3.262406e-14 -5.552077e-13 5.86271e-13
                  ]
                }
              }
              Solid {
                translation 0.0235 0.0001 0.035204
                rotation 0.5773502691896258 0.5773502691896258 -0.5773502691896258 2.094395
                children [
                  SAHRV74_u_neck_bone_leftMesh {
                  }
                ]
                name "u_neck_bone_left"
                boundingObject Pose {
                  translation 0.009875 0.0015 0.0001
                  rotation 0 1 0 0
                  children [
                    Box {
                      size 0.04085 0.003 0.03
                    }
                  ]
                }
                physics Physics {
                  density -1
                  mass 0.004792
                  centerOfMass [
                    0.012953 0.0015 0.0001
                  ]
                  inertiaMatrix [
                    3.650961e-07 9.043631e-07 5.464543e-07
                    3.262406e-14 -5.552077e-13 5.86271e-13
                  ]
                }
              }
            ]
            name "u_neck_1"
            boundingObject Pose {
              translation 0 0 0.007004
              rotation 0 1 0 0
              children [
                Box {
                  size 0.053 0.047 0.007
                }
              ]
            }
            physics Physics {
              density -1
              mass 0.016313
              centerOfMass [
                0 0 0.005978
              ]
              inertiaMatrix [
                2.000976e-06 4.314258e-06 6.176757e-06
                3.645197e-12 -7.922845e-15 -1.304717e-14
              ]
            }
          }
        }
        DEF left_hip_yaw HingeJoint {
          jointParameters HingeJointParameters {
            position 1.1009699963417417e-06
            axis 0 0 1
            anchor 0.097033 0.014615 -0.0089
            dampingConstant 1.23
            staticFriction 2.55
          }
          device [
            RotationalMotor {
              name "left_hip_yaw"
              maxVelocity 8.17
              maxTorque 7.3
            }
            PositionSensor {
              name "left_hip_yaw_sensor"
              resolution 0.0015
            }
          ]
          endPoint Solid {
            translation 0.097033 0.014615 -0.0089
            rotation 0.7064884002129213 -0.7077246218442504 -9.533263442947696e-14 3.141593
            children [
              SAHRV74_u_block_2Mesh {
              }
              Solid {
                translation 0.032918 -5.8e-05 0.037
                rotation 0.5770130724399566 0.5780240725668806 -0.5770130724399566 2.093384
                children [
                  SAHRV74_u_block_2_bone1Mesh {
                  }
                ]
                name "u_block_2_bone1"
                boundingObject Pose {
                  translation 0.008725 0.0015 0
                  rotation 0 1 0 0
                  children [
                    Box {
                      size 0.04455 0.003 0.03
                    }
                  ]
                }
                physics Physics {
                  density -1
                  mass 0.005121
                  centerOfMass [
                    0.011155 0.001454 0
                  ]
                  inertiaMatrix [
                    3.925086e-07 1.040646e-06 6.556397e-07
                    4.042085e-09 -4.851645e-13 -1.180276e-12
                  ]
                }
              }
              Solid {
                translation -0.023385 4.1e-05 0.037
                rotation 0.5770137400781608 0.5780227396236464 -0.5770137400781608 2.093386
                children [
                  SAHRV74_u_block_2_bone2Mesh {
                  }
                ]
                name "u_block_2_bone2"
                boundingObject Pose {
                  translation 0.008725 -0.0015 0
                  rotation 0 1 0 0
                  children [
                    Box {
                      size 0.04455 0.003 0.03
                    }
                  ]
                }
                physics Physics {
                  density -1
                  mass 0.00388
                  centerOfMass [
                    0.01298 -0.001198 0
                  ]
                  inertiaMatrix [
                    3.021668e-07 7.907772e-07 4.929442e-07
                    5.579849e-09 -2.784248e-13 -4.28893e-15
                  ]
                }
              }
              DEF left_hip_roll HingeJoint {
                jointParameters HingeJointParameters {
                  position -8.363546788298096e-07
                  anchor 0 0 0.04
                  dampingConstant 1.23
                  staticFriction 2.55
                }
                device [
                  RotationalMotor {
                    name "left_hip_roll"
                    maxVelocity 5.76
                  }
                  PositionSensor {
                    name "left_hip_roll_sensor"
                    resolution 0.0015
                  }
                ]
                endPoint Solid {
                  translation 0 0 0.04
                  rotation -0.5780242334755404 -0.577012750621918 0.5770132330672685 2.0933854832907874
                  children [
                    SAHRV74_mx106_block_2Mesh {
                    }
                    DEF left_hip_pitch HingeJoint {
                      jointParameters HingeJointParameters {
                        position 2.8025080050996233e-06
                        axis -1 0 0
                        dampingConstant 1.23
                        staticFriction 2.55
                      }
                      device [
                        RotationalMotor {
                          name "left_hip_pitch"
                          maxVelocity 5.76
                        }
                        PositionSensor {
                          name "left_hip_pitch_sensor"
                          resolution 0.0015
                        }
                      ]
                      endPoint Solid {
                        rotation -1.4012544604707458e-06 0.9999999999980365 -1.401254002547975e-06 1.5707960000019319
                        children [
                          SAHRV74_left_knee_1Mesh {
                          }
                          DEF left_knee HingeJoint {
                            jointParameters HingeJointParameters {
                              position 2.5070278436188e-06
                              axis 0 0 -1
                              anchor -2.2e-05 -0.141 -0.029
                              dampingConstant 1.23
                              staticFriction 2.55
                            }
                            device [
                              RotationalMotor {
                                name "left_knee"
                                maxVelocity 5.76
                              }
                              PositionSensor {
                                name "left_knee_sensor"
                                resolution 0.0015
                              }
                            ]
                            endPoint Solid {
                              translation -2.2e-05 -0.141 -0.029
                              rotation 0.9999999999992145 -1.25351392180907e-06 2.1711500831723616e-13 3.141593
                              children [
                                SAHRV74_tibia_2Mesh {
                                }
                                DEF left_ankle_pitch HingeJoint {
                                  jointParameters HingeJointParameters {
                                    position 2.2499386012961778e-06
                                    axis 0 0 1
                                    anchor 0 0.14 0
                                    dampingConstant 1.23
                                    staticFriction 2.55
                                  }
                                  device [
                                    RotationalMotor {
                                      name "left_ankle_pitch"
                                      maxVelocity 5.76
                                    }
                                    PositionSensor {
                                      name "left_ankle_pitch_sensor"
                                      resolution 0.0015
                                    }
                                  ]
                                  endPoint Solid {
                                    translation 0 0.14 0
                                    rotation 0.9999999999993673 1.1249693006478496e-06 -1.9485042392097943e-13 3.141593
                                    children [
                                      SAHRV74_mx106_block_mir_2Mesh {
                                      }
                                      DEF left_ankle_roll HingeJoint {
                                        jointParameters HingeJointParameters {
                                          position 8.373243589178963e-07
                                          anchor 0.008271 0 0.029
                                          dampingConstant 1.23
                                          staticFriction 2.55
                                        }
                                        device [
                                          RotationalMotor {
                                            name "left_ankle_roll"
                                            maxVelocity 5.76
                                          }
                                          PositionSensor {
                                            name "left_ankle_roll_sensor"
                                            resolution 0.0015
                                          }
                                        ]
                                        endPoint Solid {
                                          translation 0.008271 0 0.029
                                          rotation 0.7071067811864807 2.9603886612178064e-07 -0.7071067811865523 3.141593592077732
                                          children [
                                            SAHRV74_left_foot_1Mesh {
                                            }
                                            Solid {
                                              translation 0.0055 0.04 -0.086
                                              rotation 1 0 0 1.5708
                                              children [
                                                SAHRV74_right_foot_1_7_foot_protectionMesh {
                                                }
                                              ]
                                              name "left_foot_1_0_foot_protection"
                                              boundingObject Pose {
                                                translation 0 0.0205 0.0105
                                                rotation 0 1 0 0
                                                children [
                                                  Box {
                                                    size 0.09 0.065 0.021
                                                  }
                                                ]
                                              }
                                              physics Physics {
                                                density -1
                                                mass 0.24554
                                                centerOfMass [
                                                  -0.001997 0.016481 0.014896
                                                ]
                                                inertiaMatrix [
                                                  0.0001397844 0.0001002943 0.0001590171
                                                  -1.027646e-11 -1.617452e-11 -1.411914e-05
                                                ]
                                              }
                                            }
                                            Solid {
                                              translation 0.0055 0.06025 -0.006999
                                              rotation -0.5839271499484238 -0.5894541513677193 0.5581871433385694 4.166319
                                              children [
                                                SAHRV74_left_footMesh {
                                                }
                                              ]
                                              name "left_foot"
                                            }
                                            TouchSensor {
                                              translation -0.032498653171083136 0.05988872280142584 -0.07779796059852773
                                              rotation -0.7071061579643708 -0.7071074044081701 8.205744009585552e-08 -3.1415926510886445
                                              children [
                                                DEF left_foot_cleat_front_right Solid {
                                                  rotation 1.63397448238452e-07 1.63397448238452e-07 0.9999999999999734 1.5707963267949232
                                                  children [
                                                    SAHRV74_left_foot_cleat_front_rightMesh {
                                                    }
                                                  ]
                                                  name "left_foot_cleat_front_right"
                                                }
                                              ]
                                              name "/left_pressure/pressure_0"
                                              boundingObject Pose {
                                                translation -0.008 4.898587196589413e-19 -4.898587196589413e-19
                                                rotation 0.5773502063608033 0.5773502063608033 0.5773503948472501 2.0943949139067692
                                                children [
                                                  Capsule {
                                                    height 0.001
                                                    radius 0.008
                                                    subdivision 16
                                                  }
                                                ]
                                              }
                                              physics Physics {
                                                density -1
                                                mass 0.001078
                                                centerOfMass [
                                                  0 0.008947 0
                                                ]
                                                inertiaMatrix [
                                                  3.7612e-08 3.2706e-08 3.7612e-08
                                                  -6.8469e-23 -1.2628e-24 3.036e-22
                                                ]
                                              }
                                              type "force"
                                              lookupTable [
                                                -392.266 -8388607 0
                                                392.266 8388608 0
                                              ]
                                            }
                                            TouchSensor {
                                              translation 0.0434850786105232 0.05986153231820381 -0.07779044201174967
                                              rotation -0.7071059508621511 -0.7071076115097801 5.166561789975409e-07 -3.1415921433252736
                                              children [
                                                DEF left_foot_cleat_front_left Solid {
                                                  rotation 1.63397448238452e-07 1.63397448238452e-07 0.9999999999999734 1.5707963267949232
                                                  children [
                                                    SAHRV74_left_foot_cleat_front_leftMesh {
                                                    }
                                                  ]
                                                  name "left_foot_cleat_front_left"
                                                }
                                              ]
                                              name "/left_pressure/pressure_3"
                                              boundingObject Pose {
                                                translation -0.008 4.898587196589413e-19 -4.898587196589413e-19
                                                rotation 0.5773502063608033 0.5773502063608033 0.5773503948472501 2.0943949139067692
                                                children [
                                                  Capsule {
                                                    height 0.001
                                                    radius 0.008
                                                    subdivision 16
                                                  }
                                                ]
                                              }
                                              physics Physics {
                                                density -1
                                                mass 0.001078
                                                centerOfMass [
                                                  0 0.008947 0
                                                ]
                                                inertiaMatrix [
                                                  3.7612e-08 3.2706e-08 3.7612e-08
                                                  -5.9557e-23 2.2269e-24 -1.2471e-22
                                                ]
                                              }
                                              type "force"
                                              lookupTable [
                                                -392.266 -8388607 0
                                                392.266 8388608 0
                                              ]
                                            }
                                            TouchSensor {
                                              translation -0.03249517774249311 0.0598418965760061 0.06379615997226162
                                              rotation -0.7071065013847737 -0.7071070609881964 1.4261807836199941e-07 -3.141592235901149
                                              children [
                                                DEF left_foot_cleat_back_right Solid {
                                                  rotation 1.63397448238452e-07 1.63397448238452e-07 0.9999999999999734 1.5707963267949232
                                                  children [
                                                    SAHRV74_left_foot_cleat_back_rightMesh {
                                                    }
                                                  ]
                                                  name "left_foot_cleat_back_right"
                                                }
                                              ]
                                              name "/left_pressure/pressure_1"
                                              boundingObject Pose {
                                                translation -0.008 4.898587196589413e-19 -4.898587196589413e-19
                                                rotation 0.5773502063608033 0.5773502063608033 0.5773503948472501 2.0943949139067692
                                                children [
                                                  Capsule {
                                                    height 0.001
                                                    radius 0.008
                                                    subdivision 16
                                                  }
                                                ]
                                              }
                                              physics Physics {
                                                density -1
                                                mass 0.001078
                                                centerOfMass [
                                                  0 0.008947 0
                                                ]
                                                inertiaMatrix [
                                                  3.7612e-08 3.2706e-08 3.7612e-08
                                                  6.3364e-23 2.1586e-24 2.8599e-22
                                                ]
                                              }
                                              type "force"
                                              lookupTable [
                                                -392.266 -8388607 0
                                                392.266 8388608 0
                                              ]
                                            }
                                            TouchSensor {
                                              translation 0.04348472556576932 0.059802496995025954 0.06380588023948164
                                              rotation -0.7071063736881146 -0.7071071886844249 6.735377925374783e-07 -3.1415914792859003
                                              children [
                                                DEF left_foot_cleat_back_left Solid {
                                                  rotation 1.63397448238452e-07 1.63397448238452e-07 0.9999999999999734 1.5707963267949232
                                                  children [
                                                    SAHRV74_left_foot_cleat_back_leftMesh {
                                                    }
                                                  ]
                                                  name "left_foot_cleat_back_left"
                                                }
                                              ]
                                              name "/left_pressure/pressure_2"
                                              boundingObject Pose {
                                                translation -0.008 4.898587196589413e-19 -4.898587196589413e-19
                                                rotation 0.5773502063608033 0.5773502063608033 0.5773503948472501 2.0943949139067692
                                                children [
                                                  Capsule {
                                                    height 0.001
                                                    radius 0.008
                                                    subdivision 16
                                                  }
                                                ]
                                              }
                                              physics Physics {
                                                density -1
                                                mass 0.001078
                                                centerOfMass [
                                                  0 0.008947 0
                                                ]
                                                inertiaMatrix [
                                                  3.7612e-08 3.2706e-08 3.7612e-08
                                                  -3.9867e-22 2.0182e-24 2.9095e-22
                                                ]
                                              }
                                              type "force"
                                              lookupTable [
                                                -392.266 -8388607 0
                                                392.266 8388608 0
                                              ]
                                            }
                                            Solid {
                                              translation 0 0 0.032896
                                              rotation -0.5773502691896258 -0.5773502691896258 0.5773502691896258 2.094395
                                              children [
                                                SAHRV74_left_foot_bone_backMesh {
                                                }
                                              ]
                                              name "left_foot_bone_back"
                                              boundingObject Pose {
                                                translation 0.01623 0.002725 0
                                                rotation 0 1 0 0
                                                children [
                                                  Box {
                                                    size 0.04755 0.003 0.03
                                                  }
                                                ]
                                              }
                                              physics Physics {
                                                density -1
                                                mass 0.004639
                                                centerOfMass [
                                                  0.019897 0.002479 0
                                                ]
                                                inertiaMatrix [
                                                  3.607061e-07 1.03068e-06 6.756077e-07
                                                  -7.187226e-09 5.660389e-13 4.324619e-16
                                                ]
                                              }
                                            }
                                            Solid {
                                              translation 0 0 -0.023444
                                              rotation -0.5773509358554485 -0.5773509358554485 0.5773489358556708 2.094397
                                              children [
                                                SAHRV74_left_foot_bone_frontMesh {
                                                }
                                              ]
                                              name "left_foot_bone_front"
                                              boundingObject Pose {
                                                translation 0.015005 -0.000275 0
                                                rotation 0 1 0 0
                                                children [
                                                  Box {
                                                    size 0.05 0.003 0.03
                                                  }
                                                ]
                                              }
                                              physics Physics {
                                                density -1
                                                mass 0.005641
                                                centerOfMass [
                                                  0.017355 -0.000232 0
                                                ]
                                                inertiaMatrix [
                                                  4.32052e-07 1.338966e-06 9.151917e-07
                                                  -4.804138e-09 4.374171e-12 1.389117e-12
                                                ]
                                              }
                                            }
                                          ]
                                          name "left_foot_1 [foot]"
                                          boundingObject Pose {
                                            translation 0.0055 0.0335 -0.006999
                                            rotation 0 1 0 0
                                            children [
                                              Box {
                                                size 0.092 0.019 0.157609
                                              }
                                            ]
                                          }
                                          physics Physics {
                                            density -1
                                            mass 0.197905
                                            centerOfMass [
                                              0.005102 0.036791 0.003379
                                            ]
                                            inertiaMatrix [
                                              0.0003693502 0.0004561848 8.985304e-05
                                              -4.136806e-07 1.093774e-05 4.359026e-07
                                            ]
                                          }
                                        }
                                      }
                                      Solid {
                                        translation 0 0 0.0095
                                        rotation 0 0 1 1.570796
                                        children [
                                          SAHRV74_joint_block03Mesh {
                                          }
                                          Solid {
                                            translation 0 0 -0.0006
                                            rotation 0.5773502691896258 -0.5773502691896258 0.5773502691896258 2.094395
                                            children [
                                              SAHRV74_dubel03Mesh {
                                              }
                                            ]
                                            name "dubel03"
                                            boundingObject Pose {
                                              translation 0.0201 -0.01805 -0.0479
                                              rotation 0 1 0 0
                                              children [
                                                Box {
                                                  size 0.0402 0.0651 0.049
                                                }
                                              ]
                                            }
                                            physics Physics {
                                              density -1
                                              mass 0.159507
                                              centerOfMass [
                                                0.020104 -0.015778 -0.048989
                                              ]
                                              inertiaMatrix [
                                                7.602558e-05 4.229576e-05 6.034857e-05
                                                -3.06858e-09 4.247805e-09 -1.841894e-06
                                              ]
                                            }
                                          }
                                        ]
                                        name "joint_block03"
                                        boundingObject Pose {
                                          translation 0.0325 0.02355 0.0195
                                          rotation 0 1 0 0
                                          children [
                                            Box {
                                              size 0.036 0.0177 0.039
                                            }
                                          ]
                                        }
                                        physics Physics {
                                          density -1
                                          mass 0.014404
                                          centerOfMass [
                                            0.033694 0.023894 0.019497
                                          ]
                                          inertiaMatrix [
                                            2.951288e-06 4.145151e-06 1.362015e-06
                                            8.65408e-09 -1.349458e-10 1.370066e-10
                                          ]
                                        }
                                      }
                                    ]
                                    name "mx106_block_mir_2"
                                    boundingObject Pose {
                                      translation 0.00492 0.01805 0.0275
                                      rotation 0 1 0 0
                                      children [
                                        Box {
                                          size 0.05004 0.0651 0.049
                                        }
                                      ]
                                    }
                                    physics Physics {
                                      density -1
                                      mass 0.173092
                                      centerOfMass [
                                        0.001897 0.014587 0.028621
                                      ]
                                      inertiaMatrix [
                                        7.865863e-05 4.405545e-05 6.132583e-05
                                        2.74733e-08 -4.239819e-09 -1.841894e-06
                                      ]
                                    }
                                  }
                                }
                                Solid {
                                  translation -0.001414 0.03505 -0.003
                                  rotation -1 0 0 3.141593
                                  children [
                                    SAHRV74_tibia_21Mesh {
                                    }
                                    Solid {
                                      translation 0.004916 -0.056985 -0.004
                                      rotation -0.04942100176618308 -0.9987780356938307 0 3.141593
                                      children [
                                        SAHRV74_left_shin_panelMesh {
                                          color 1 0 0
                                        }
                                      ]
                                      name "left_shin_panel"
                                      boundingObject Pose {
                                        translation 0 0 -0.0025
                                        rotation 0 1 0 0
                                        children [
                                          Box {
                                            size 0.052303 0.065 0.007
                                          }
                                        ]
                                      }
                                      physics Physics {
                                        density -1
                                        mass 0.007135
                                        centerOfMass [
                                          0 -0.000401 -0.000397
                                        ]
                                        inertiaMatrix [
                                          2.3451e-06 1.5543e-06 3.8739e-06
                                          9.5493e-16 -7.3543e-16 1.0029e-09
                                        ]
                                      }
                                    }
                                  ]
                                  name "tibia_21"
                                  boundingObject Group {
                                    children [
                                      Pose {
                                        translation 0.007211 0.02 -0.0015
                                        rotation 0 0 1 0.3
                                        children [
                                          Box {
                                            size 0.04 0.06 0.003
                                          }
                                        ]
                                      }
                                      Pose {
                                        translation 0.007211 -0.05 -0.0015
                                        rotation 0 0 1 -0.15
                                        children [
                                          Box {
                                            size 0.04 0.09 0.003
                                          }
                                        ]
                                      }
                                    ]
                                  }
                                  physics Physics {
                                    density -1
                                    mass 0.024844
                                    centerOfMass [
                                      0.005114 -0.034363 -0.0015
                                    ]
                                    inertiaMatrix [
                                      5.800814e-05 4.063772e-06 6.203465e-05
                                      -1.245392e-06 1.245521e-21 -8.414267e-21
                                    ]
                                  }
                                }
                                Solid {
                                  translation 0.02192 0.058385 -0.055
                                  rotation 0 0 1 3.1416
                                  children [
                                    SAHRV74_tibia_22Mesh {
                                    }
                                  ]
                                  name "tibia_22"
                                  boundingObject Group {
                                    children [
                                      Pose {
                                        translation 0.016456 0.043 -0.0015
                                        rotation 0 0 1 -0.3
                                        children [
                                          Box {
                                            size 0.04 0.06 0.003
                                          }
                                        ]
                                      }
                                      Pose {
                                        translation 0.016456 -0.028 -0.0015
                                        rotation 0 0 1 0.15
                                        children [
                                          Box {
                                            size 0.04 0.09 0.003
                                          }
                                        ]
                                      }
                                    ]
                                  }
                                  physics Physics {
                                    density -1
                                    mass 0.024844
                                    centerOfMass [
                                      0.011187 0.0015 0.018123
                                    ]
                                    inertiaMatrix [
                                      4.046108e-06 6.203465e-05 5.802581e-05
                                      3.313928e-20 -7.731813e-07 1.62857e-19
                                    ]
                                  }
                                }
                              ]
                              name "tibia_2"
                              boundingObject Pose {
                                translation 0.008485 0.048485 -0.029
                                rotation 0 1 0 0
                                children [
                                  Box {
                                    size 0.02687 0.02687 0.052
                                  }
                                ]
                              }
                              physics Physics {
                                density -1
                                mass 0.012466
                                centerOfMass [
                                  0.008485 0.048485 -0.029
                                ]
                                inertiaMatrix [
                                  4.141024e-06 4.141024e-06 1.490545e-06
                                  -7.185554e-07 -4.143752e-12 1.123388e-12
                                ]
                              }
                            }
                          }
                          Solid {
                            translation -2.2e-05 -0.055 -0.03
                            rotation 0 1 0 3.141593
                            children [
                              SAHRV74_left_knee_bone_1Mesh {
                              }
                              Solid {
                                rotation 0 1 0 0
                                children [
                                  SAHRV74_left_hip_panelMesh {
                                    color 1 0 0
                                  }
                                ]
                                name "left_hip_panel"
                                boundingObject Pose {
                                  translation 0 0 -0.0025
                                  rotation 0 1 0 0
                                  children [
                                    Box {
                                      size 0.058 0.07 0.007
                                    }
                                  ]
                                }
                                physics Physics {
                                  density -1
                                  mass 0.008452
                                  centerOfMass [
                                    0 0 -0.000328
                                  ]
                                  inertiaMatrix [
                                    3.2593e-06 2.2894e-06 5.5224e-06
                                    -9.9949e-16 2.1442e-21 -7.7935e-22
                                  ]
                                }
                              }
                            ]
                            name "left_knee_bone_1"
                            boundingObject Pose {
                              translation 0 0.009439 -0.0025
                              rotation 0 1 0 0
                              children [
                                Box {
                                  size 0.044 0.118878 0.003
                                }
                              ]
                            }
                            physics Physics {
                              density -1
                              mass 0.016935
                              centerOfMass [
                                0 0.004535 -0.0025
                              ]
                              inertiaMatrix [
                                2.049741e-05 2.918984e-06 2.339099e-05
                                5.883325e-21 1.946918e-21 9.866665e-21
                              ]
                            }
                          }
                          Solid {
                            translation -2.2e-05 -0.128 0.026
                            rotation -0.5773502691896258 -0.5773502691896258 0.5773502691896258 2.094395
                            children [
                              SAHRV74_left_knee_bone_2Mesh {
                              }
                            ]
                            name "left_knee_bone_2"
                            boundingObject Pose {
                              translation 0.082439 -0.0015 0
                              rotation 0 1 0 0
                              children [
                                Box {
                                  size 0.118878 0.003 0.044
                                }
                              ]
                            }
                            physics Physics {
                              density -1
                              mass 0.016935
                              centerOfMass [
                                0.077535 -0.0015 0
                              ]
                              inertiaMatrix [
                                2.918984e-06 2.339099e-05 2.049741e-05
                                1.296383e-21 -7.377452e-21 -4.523817e-12
                              ]
                            }
                          }
                        ]
                        name "left_knee_1"
                        boundingObject Pose {
                          translation -2.2e-05 -0.12195 0
                          rotation 0 1 0 0
                          children [
                            Box {
                              size 0.049 0.0671 0.05
                            }
                          ]
                        }
                        physics Physics {
                          density -1
                          mass 0.185809
                          centerOfMass [
                            -1.9e-05 -0.121892 7e-05
                          ]
                          inertiaMatrix [
                            7.705682e-05 4.823411e-05 6.693444e-05
                            3.071459e-09 -4.231979e-09 -1.841894e-06
                          ]
                        }
                      }
                    }
                    Solid {
                      translation 0 0 0.014722
                      rotation -0.577349935856137 0.577349935856137 -0.5773509358560258 2.094394
                      children [
                        SAHRV74_joint_block01Mesh {
                        }
                        Solid {
                          translation 0 -0.0087 0
                          rotation 0.5773502691896258 -0.5773502691896258 0.5773502691896258 2.094395
                          children [
                            SAHRV74_dubel01Mesh {
                            }
                          ]
                          name "dubel01"
                          boundingObject Pose {
                            translation 0 -0.01805 0.0245
                            rotation 0 1 0 0
                            children [
                              Box {
                                size 0.0402 0.0651 0.049
                              }
                            ]
                          }
                          physics Physics {
                            density -1
                            mass 0.159507
                            centerOfMass [
                              -4e-06 -0.015778 0.025589
                            ]
                            inertiaMatrix [
                              7.602558e-05 4.229576e-05 6.034857e-05
                              3.06858e-09 4.247805e-09 1.841894e-06
                            ]
                          }
                        }
                      ]
                      name "joint_block01"
                      boundingObject Pose {
                        translation 0.0325 -0.00885 0
                        rotation 0 1 0 0
                        children [
                          Box {
                            size 0.036 0.0177 0.039
                          }
                        ]
                      }
                      physics Physics {
                        density -1
                        mass 0.014404
                        centerOfMass [
                          0.033694 -0.009194 3e-06
                        ]
                        inertiaMatrix [
                          2.951288e-06 4.145151e-06 1.362015e-06
                          -8.654061e-09 1.349344e-10 1.370113e-10
                        ]
                      }
                    }
                  ]
                  name "mx106_block_2"
                  boundingObject Pose {
                    translation 0 -0.01805 -0.004898
                    rotation 0 1 0 0
                    children [
                      Box {
                        size 0.052 0.0651 0.05004
                      }
                    ]
                  }
                  physics Physics {
                    density -1
                    mass 0.176283
                    centerOfMass [
                      7.4e-05 -0.014323 -0.001834
                    ]
                    inertiaMatrix [
                      6.169003e-05 4.423969e-05 7.884286e-05
                      1.841893e-06 -4.266636e-09 2.133902e-08
                    ]
                  }
                }
              }
            ]
            name "u_block_2"
            boundingObject Pose {
              translation 0.004722 0 0.008
              rotation 0 1 0 0
              children [
                Box {
                  size 0.056444 0.03 0.006
                }
              ]
            }
            physics Physics {
              density -1
              mass 0.01751
              centerOfMass [
                0.004374 -8e-06 0.007365
              ]
              inertiaMatrix [
                3.135662e-06 4.771173e-06 7.793656e-06
                2.859586e-09 -9.785036e-09 1.719398e-11
              ]
            }
          }
        }
        DEF right_hip_yaw HingeJoint {
          jointParameters HingeJointParameters {
            position 8.981901631865191e-07
            axis 0 0 1
            anchor 0.004283 0.014615 -0.0089
            dampingConstant 1.23
            staticFriction 2.55
          }
          device [
            RotationalMotor {
              name "right_hip_yaw"
              maxVelocity 8.17
              maxTorque 7.3
            }
            PositionSensor {
              name "right_hip_yaw_sensor"
              resolution 0.0015
            }
          ]
          endPoint Solid {
            translation 0.004283 0.014615 -0.0089
            rotation 0.7071070987446539 -0.7071064636282985 -7.778556000258221e-14 3.141593
            children [
              SAHRV74_u_block_1Mesh {
              }
              Solid {
                translation 0.032918 0 0.037
                rotation 0.577349935856137 0.5773509358560258 -0.577349935856137 2.094394
                children [
                  SAHRV74_u_block_1_bone1Mesh {
                  }
                ]
                name "u_block_1_bone1"
                boundingObject Pose {
                  translation 0.008725 0.0015 0
                  rotation 0 1 0 0
                  children [
                    Box {
                      size 0.04455 0.003 0.03
                    }
                  ]
                }
                physics Physics {
                  density -1
                  mass 0.005121
                  centerOfMass [
                    0.011155 0.001454 0
                  ]
                  inertiaMatrix [
                    3.925086e-07 1.040646e-06 6.556397e-07
                    4.042085e-09 -4.851645e-13 -1.180276e-12
                  ]
                }
              }
              Solid {
                translation -0.023385 0 0.037
                rotation 0.5773506025225371 0.5773496025232256 -0.5773506025225371 2.094396
                children [
                  SAHRV74_u_block_1_bone2Mesh {
                  }
                ]
                name "u_block_1_bone2"
                boundingObject Pose {
                  translation 0.008725 -0.0015 0
                  rotation 0 1 0 0
                  children [
                    Box {
                      size 0.04455 0.003 0.03
                    }
                  ]
                }
                physics Physics {
                  density -1
                  mass 0.005121
                  centerOfMass [
                    0.011155 -0.001454 0
                  ]
                  inertiaMatrix [
                    3.925086e-07 1.040646e-06 6.556397e-07
                    -4.042085e-09 4.725258e-13 2.355991e-14
                  ]
                }
              }
              DEF right_hip_roll HingeJoint {
                jointParameters HingeJointParameters {
                  position 2.9485192931868337e-07
                  anchor 0 0 0.04
                  dampingConstant 1.23
                  staticFriction 2.55
                }
                device [
                  RotationalMotor {
                    name "right_hip_roll"
                    maxVelocity 5.76
                  }
                  PositionSensor {
                    name "right_hip_roll_sensor"
                    resolution 0.0015
                  }
                ]
                endPoint Solid {
                  translation 0 0 0.04
                  rotation -0.5773508791117193 0.5773500493447085 -0.5773498791119537 2.0943938297669678
                  children [
                    SAHRV74_mx106_block_mir_1Mesh {
                    }
                    DEF right_hip_pitch HingeJoint {
                      jointParameters HingeJointParameters {
                        position -5.124987562188204e-08
                        anchor -0.029 0 -2.2e-05
                        dampingConstant 1.23
                        staticFriction 2.55
                      }
                      device [
                        RotationalMotor {
                          name "right_hip_pitch"
                          maxVelocity 5.76
                        }
                        PositionSensor {
                          name "right_hip_pitch_sensor"
                          resolution 0.0015
                        }
                      ]
                      endPoint Solid {
                        translation -0.029 0 -2.2e-05
                        rotation -2.5624946185047148e-08 0.9999999999999993 -2.562493781094256e-08 1.5707959999999674
                        children [
                          SAHRV74_right_knee_1Mesh {
                          }
                          DEF right_knee HingeJoint {
                            jointParameters HingeJointParameters {
                              position 1.5942577133967277e-06
                              axis 0 0 1
                              anchor 0 -0.141 0.055
                              dampingConstant 1.23
                              staticFriction 2.55
                            }
                            device [
                              RotationalMotor {
                                name "right_knee"
                                maxVelocity 5.76
                              }
                              PositionSensor {
                                name "right_knee_sensor"
                                resolution 0.0015
                              }
                            ]
                            endPoint Solid {
                              translation 0 -0.141 0.055
                              rotation 0 0 1 3.1415945942577133
                              children [
                                SAHRV74_tibia_1Mesh {
                                }
                                DEF right_ankle_pitch HingeJoint {
                                  jointParameters HingeJointParameters {
                                    position 2.936764257026407e-06
                                    axis 0 0 1
                                    anchor 0 0.14 -0.026
                                    dampingConstant 1.23
                                    staticFriction 2.55
                                  }
                                  device [
                                    RotationalMotor {
                                      name "right_ankle_pitch"
                                      maxVelocity 5.76
                                    }
                                    PositionSensor {
                                      name "right_ankle_pitch_sensor"
                                      resolution 0.0015
                                    }
                                  ]
                                  endPoint Solid {
                                    translation 0 0.14 -0.026
                                    rotation 0 0 -1 3.1415900632357427
                                    children [
                                      SAHRV74_mx106_block_1Mesh {
                                      }
                                      DEF right_ankle_roll HingeJoint {
                                        jointParameters HingeJointParameters {
                                          position -2.5945085608198635e-06
                                          axis -1 0 0
                                          anchor -0.006301 0 0
                                          dampingConstant 1.23
                                          staticFriction 2.55
                                        }
                                        device [
                                          RotationalMotor {
                                            name "right_ankle_roll"
                                            maxVelocity 5.76
                                          }
                                          PositionSensor {
                                            name "right_ankle_roll_sensor"
                                            resolution 0.0015
                                          }
                                        ]
                                        endPoint Solid {
                                          translation -0.006301 0 0
                                          rotation 1.297254704344649e-06 0.9999999999983171 1.2972542804084732e-06 1.5707960000016532
                                          children [
                                            SAHRV74_right_foot_1Mesh {
                                            }
                                            TouchSensor {
                                              translation -0.032490021526500934 -0.0598975899072131 -0.07976248498507132
                                              rotation -6.440559352044864e-08 -8.547799009192949e-08 -0.9999999999999941 1.5707965811634221
                                              children [
                                                DEF right_foot_clear_front_left Solid {
                                                  rotation 1.63397448238452e-07 1.63397448238452e-07 0.9999999999999734 1.5707963267949232
                                                  children [
                                                    SAHRV74_right_foot_clear_front_leftMesh {
                                                    }
                                                  ]
                                                  name "right_foot_cleat_front_left"
                                                }
                                              ]
                                              name "/right_pressure/pressure_3"
                                              boundingObject Pose {
                                                translation -0.008 4.898587196589413e-19 -4.898587196589413e-19
                                                rotation 0.5773502063608033 0.5773502063608033 0.5773503948472501 2.0943949139067692
                                                children [
                                                  Capsule {
                                                    height 0.001
                                                    radius 0.008
                                                    subdivision 16
                                                  }
                                                ]
                                              }
                                              physics Physics {
                                                density -1
                                                mass 0.001078
                                                centerOfMass [
                                                  0 0.008947 0
                                                ]
                                                inertiaMatrix [
                                                  3.7612e-08 3.2706e-08 3.7612e-08
                                                  -6.2053e-23 1.6066e-24 8.1651e-24
                                                ]
                                              }
                                              type "force"
                                              lookupTable [
                                                -392.266 -8388607 0
                                                392.266 8388608 0
                                              ]
                                            }
                                            TouchSensor {
                                              translation -0.032492597870189543 -0.0598506959932574 0.06183295574489023
                                              rotation 1.0765720671441141e-07 6.097706873561937e-08 -0.9999999999999923 1.5707983140119819
                                              children [
                                                DEF right_foot_cleat_back_left Solid {
                                                  rotation 1.63397448238452e-07 1.63397448238452e-07 0.9999999999999734 1.5707963267949232
                                                  children [
                                                    SAHRV74_right_foot_cleat_back_leftMesh {
                                                    }
                                                  ]
                                                  name "right_foot_cleat_back_left"
                                                }
                                              ]
                                              name "/right_pressure/pressure_2"
                                              boundingObject Pose {
                                                translation -0.008 4.898587196589413e-19 -4.898587196589413e-19
                                                rotation 0.5773502063608033 0.5773502063608033 0.5773503948472501 2.0943949139067692
                                                children [
                                                  Capsule {
                                                    height 0.001
                                                    radius 0.008
                                                    subdivision 16
                                                  }
                                                ]
                                              }
                                              physics Physics {
                                                density -1
                                                mass 0.001078
                                                centerOfMass [
                                                  0 0.008947 0
                                                ]
                                                inertiaMatrix [
                                                  3.7612e-08 3.2706e-08 3.7612e-08
                                                  3.9304e-23 -2.7141e-25 2.7839e-22
                                                ]
                                              }
                                              type "force"
                                              lookupTable [
                                                -392.266 -8388607 0
                                                392.266 8388608 0
                                              ]
                                            }
                                            TouchSensor {
                                              translation 0.04349284753459126 -0.05987511845526217 0.06182858904105726
                                              rotation -2.3856462717806617e-07 -3.1901379612204077e-07 -0.9999999999999207 1.5707981214963072
                                              children [
                                                DEF right_foot_cleat_back_right Solid {
                                                  rotation 1.63397448238452e-07 1.63397448238452e-07 0.9999999999999734 1.5707963267949232
                                                  children [
                                                    SAHRV74_right_foot_cleat_back_rightMesh {
                                                    }
                                                  ]
                                                  name "right_foot_cleat_back_right"
                                                }
                                              ]
                                              name "/right_pressure/pressure_1"
                                              boundingObject Pose {
                                                translation -0.008 4.898587196589413e-19 -4.898587196589413e-19
                                                rotation 0.5773502063608033 0.5773502063608033 0.5773503948472501 2.0943949139067692
                                                children [
                                                  Capsule {
                                                    height 0.001
                                                    radius 0.008
                                                    subdivision 16
                                                  }
                                                ]
                                              }
                                              physics Physics {
                                                density -1
                                                mass 0.001078
                                                centerOfMass [
                                                  0 0.008947 0
                                                ]
                                                inertiaMatrix [
                                                  3.7612e-08 3.2706e-08 3.7612e-08
                                                  -3.6811e-22 1.7469e-24 2.852e-22
                                                ]
                                              }
                                              type "force"
                                              lookupTable [
                                                -392.266 -8388607 0
                                                392.266 8388608 0
                                              ]
                                            }
                                            TouchSensor {
                                              translation 0.043495044447041 -0.05992180067531798 -0.07976882140990926
                                              rotation -3.407982266122987e-07 -3.7297525699273097e-07 -0.9999999999998723 1.5707965988554466
                                              children [
                                                DEF right_foot_cleat_front_right Solid {
                                                  rotation 1.63397448238452e-07 1.63397448238452e-07 0.9999999999999734 1.5707963267949232
                                                  children [
                                                    SAHRV74_right_foot_cleat_front_rightMesh {
                                                    }
                                                  ]
                                                  name "right_foot_cleat_front_right"
                                                }
                                              ]
                                              name "/right_pressure/pressure_0"
                                              boundingObject Pose {
                                                translation -0.008 4.898587196589413e-19 -4.898587196589413e-19
                                                rotation 0.5773502063608033 0.5773502063608033 0.5773503948472501 2.0943949139067692
                                                children [
                                                  Capsule {
                                                    height 0.001
                                                    radius 0.008
                                                    subdivision 16
                                                  }
                                                ]
                                              }
                                              physics Physics {
                                                density -1
                                                mass 0.001078
                                                centerOfMass [
                                                  0 0.008947 0
                                                ]
                                                inertiaMatrix [
                                                  3.7612e-08 3.2706e-08 3.7612e-08
                                                  -6.645e-23 -5.1302e-27 9.6515e-25
                                                ]
                                              }
                                              type "force"
                                              lookupTable [
                                                -392.266 -8388607 0
                                                392.266 8388608 0
                                              ]
                                            }
                                            Solid {
                                              translation 0.0055 -0.06025 -0.008969
                                              rotation 0.5560059760678353 -0.609900973748033 -0.5646929756939207 4.145639
                                              children [
                                                SAHRV74_right_footMesh {
                                                }
                                              ]
                                              name "right_foot"
                                            }
                                            Solid {
                                              translation 0.0055 -0.04 -0.087773
                                              rotation 0 0.7071067811865476 0.7071067811865476 3.141593
                                              children [
                                                SAHRV74_right_foot_1_7_foot_protectionMesh {
                                                }
                                              ]
                                              name "right_foot_1_7_foot_protection"
                                              boundingObject Pose {
                                                translation 0 0.0205 0.0105
                                                rotation 0 1 0 0
                                                children [
                                                  Box {
                                                    size 0.09 0.065 0.021
                                                  }
                                                ]
                                              }
                                              physics Physics {
                                                density -1
                                                mass 0.24554
                                                centerOfMass [
                                                  -0.001997 0.016481 0.014896
                                                ]
                                                inertiaMatrix [
                                                  0.0001397844 0.0001002943 0.0001590171
                                                  -1.027646e-11 -1.617452e-11 -1.411914e-05
                                                ]
                                              }
                                            }
                                            Solid {
                                              translation 0.0095 0 0.007504
                                              rotation -0.5773502691896258 0.5773502691896258 -0.5773502691896258 2.094395
                                              children [
                                                SAHRV74_right_foot_bone_backMesh {
                                                }
                                              ]
                                              name "right_foot_bone_back"
                                              boundingObject Pose {
                                                translation 0.01623 -0.020697 -0.0095
                                                rotation 0 1 0 0
                                                children [
                                                  Box {
                                                    size 0.04755 0.003 0.03
                                                  }
                                                ]
                                              }
                                              physics Physics {
                                                density -1
                                                mass 0.004639
                                                centerOfMass [
                                                  0.019897 -0.020943 -0.0095
                                                ]
                                                inertiaMatrix [
                                                  3.607061e-07 1.03068e-06 6.756077e-07
                                                  -7.187226e-09 5.660389e-13 4.32462e-16
                                                ]
                                              }
                                            }
                                            Solid {
                                              translation 0 0 -0.025436
                                              rotation -0.5773509358554485 0.5773509358554485 -0.5773489358556708 2.094397
                                              children [
                                                SAHRV74_right_foot_bone_frontMesh {
                                                }
                                              ]
                                              name "right_foot_bone_front"
                                              boundingObject Pose {
                                                translation 0.015005 -0.000297 0
                                                rotation 0 1 0 0
                                                children [
                                                  Box {
                                                    size 0.05 0.003 0.03
                                                  }
                                                ]
                                              }
                                              physics Physics {
                                                density -1
                                                mass 0.005641
                                                centerOfMass [
                                                  0.017355 -0.000254 0
                                                ]
                                                inertiaMatrix [
                                                  4.32052e-07 1.338966e-06 9.151917e-07
                                                  -4.804138e-09 4.374171e-12 1.389117e-12
                                                ]
                                              }
                                            }
                                          ]
                                          name "right_foot_1 [foot]"
                                          boundingObject Pose {
                                            translation 0.0055 -0.0335 -0.008969
                                            rotation 0 1 0 0
                                            children [
                                              Box {
                                                size 0.092 0.019 0.157609
                                              }
                                            ]
                                          }
                                          physics Physics {
                                            density -1
                                            mass 0.197905
                                            centerOfMass [
                                              0.005102 -0.036791 0.001409
                                            ]
                                            inertiaMatrix [
                                              0.0003693502 0.0004561848 8.985307e-05
                                              4.13693e-07 1.093773e-05 -4.359002e-07
                                            ]
                                          }
                                        }
                                      }
                                      Solid {
                                        translation 0 0 -0.0195
                                        rotation 0 0 1 1.570796
                                        children [
                                          SAHRV74_joint_block04Mesh {
                                          }
                                          Solid {
                                            translation 0.045 -0.0345 0.0195
                                            rotation 0.5773502691896258 0.5773502691896258 -0.5773502691896258 2.094395
                                            children [
                                              SAHRV74_dubel04Mesh {
                                              }
                                            ]
                                            name "dubel04"
                                            boundingObject Pose {
                                              translation 0 -0.027 0.014
                                              rotation 0 1 0 0
                                              children [
                                                Box {
                                                  size 0.0402 0.0651 0.049
                                                }
                                              ]
                                            }
                                            physics Physics {
                                              density -1
                                              mass 0.159507
                                              centerOfMass [
                                                4e-06 -0.020222 -0.000411
                                              ]
                                              inertiaMatrix [
                                                7.602558e-05 4.229576e-05 6.034857e-05
                                                3.068579e-09 -4.247805e-09 -1.841893e-06
                                              ]
                                            }
                                          }
                                        ]
                                        name "joint_block04"
                                        boundingObject Pose {
                                          translation 0.0325 -0.02355 0.0195
                                          rotation 0 1 0 0
                                          children [
                                            Box {
                                              size 0.036 0.0177 0.039
                                            }
                                          ]
                                        }
                                        physics Physics {
                                          density -1
                                          mass 0.014404
                                          centerOfMass [
                                            0.033694 -0.023894 0.019503
                                          ]
                                          inertiaMatrix [
                                            2.951288e-06 4.145151e-06 1.362015e-06
                                            -8.654096e-09 1.349458e-10 1.370066e-10
                                          ]
                                        }
                                      }
                                    ]
                                    name "mx106_block_1"
                                    boundingObject Pose {
                                      translation -0.00492 0.01805 -0.0015
                                      rotation 0 1 0 0
                                      children [
                                        Box {
                                          size 0.05004 0.0651 0.049
                                        }
                                      ]
                                    }
                                    physics Physics {
                                      density -1
                                      mass 0.173092
                                      centerOfMass [
                                        -0.001891 0.014587 -0.000379
                                      ]
                                      inertiaMatrix [
                                        7.865863e-05 4.405545e-05 6.132583e-05
                                        -2.133614e-08 -4.239819e-09 -1.841893e-06
                                      ]
                                    }
                                  }
                                }
                                Solid {
                                  translation -0.001699 0.035037 -0.052
                                  rotation 0 -1 0 1.570798
                                  children [
                                    SAHRV74_tibia_11Mesh {
                                    }
                                    Solid {
                                      translation -0.004 0.056999 -0.005201
                                      rotation -0.7066743372335543 -0.03496801668716116 0.7066743372335543 3.071686
                                      children [
                                        SAHRV74_right_shine_panelMesh {
                                          color 1 0 0
                                        }
                                      ]
                                      name "right_shine_panel"
                                      boundingObject Pose {
                                        translation 0 0 -0.0025
                                        rotation 0 1 0 0
                                        children [
                                          Box {
                                            size 0.052303 0.065 0.007
                                          }
                                        ]
                                      }
                                      physics Physics {
                                        density -1
                                        mass 0.007135
                                        centerOfMass [
                                          0 -0.000401 -0.000397
                                        ]
                                        inertiaMatrix [
                                          2.3451e-06 1.5543e-06 3.8739e-06
                                          -4.9229e-16 -2.3792e-12 1.0025e-09
                                        ]
                                      }
                                    }
                                  ]
                                  name "tibia_11"
                                  boundingObject Group {
                                    children [
                                      Pose {
                                        translation -0.0015 -0.02 -0.007495
                                        rotation 1 0 0 -0.3
                                        children [
                                          Box {
                                            size 0.003 0.06 0.04
                                          }
                                        ]
                                      }
                                      Pose {
                                        translation -0.0015 0.05 -0.007495
                                        rotation 1 0 0 0.15
                                        children [
                                          Box {
                                            size 0.003 0.09 0.04
                                          }
                                        ]
                                      }
                                    ]
                                  }
                                  physics Physics {
                                    density -1
                                    mass 0.024844
                                    centerOfMass [
                                      -0.0015 0.034376 -0.005399
                                    ]
                                    inertiaMatrix [
                                      6.203465e-05 4.063772e-06 5.800814e-05
                                      -1.947043e-12 -6.295029e-12 -1.245392e-06
                                    ]
                                  }
                                }
                                Solid {
                                  translation 0.02192 0.058385 0
                                  rotation -0.5739820373713977 -0.5790270376998726 0.5790270376998726 2.099455
                                  children [
                                    SAHRV74_tibia_12Mesh {
                                    }
                                  ]
                                  name "tibia_12"
                                  boundingObject Group {
                                    children [
                                      Pose {
                                        translation -0.043 -0.0015 0.016456
                                        rotation 0 1 0 0.3
                                        children [
                                          Box {
                                            size 0.06 0.003 0.04
                                          }
                                        ]
                                      }
                                      Pose {
                                        translation 0.028 -0.0015 0.016456
                                        rotation 0 1 0 -0.15
                                        children [
                                          Box {
                                            size 0.09 0.003 0.04
                                          }
                                        ]
                                      }
                                    ]
                                  }
                                  physics Physics {
                                    density -1
                                    mass 0.024844
                                    centerOfMass [
                                      0.011187 -0.0015 0.018123
                                    ]
                                    inertiaMatrix [
                                      4.046108e-06 6.203465e-05 5.802581e-05
                                      -1.152992e-20 -7.731813e-07 -4.569502e-21
                                    ]
                                  }
                                }
                              ]
                              name "tibia_1"
                              boundingObject Pose {
                                translation 0.008485 0.048485 -0.026
                                rotation 0 1 0 0
                                children [
                                  Box {
                                    size 0.02687 0.02687 0.052
                                  }
                                ]
                              }
                              physics Physics {
                                density -1
                                mass 0.012466
                                centerOfMass [
                                  0.008485 0.048485 -0.026
                                ]
                                inertiaMatrix [
                                  4.141024e-06 4.141024e-06 1.490545e-06
                                  -7.185554e-07 4.357565e-21 6.164215e-22
                                ]
                              }
                            }
                          }
                          Solid {
                            translation -2.2e-05 -0.128 0.003
                            rotation 0.5773506025225371 0.5773506025225371 0.5773496025232256 2.094396
                            children [
                              SAHRV74_right_knee_bone_1Mesh {
                              }
                              Solid {
                                translation 0.073 -0.004 2.2e-05
                                rotation 0.5773502691896258 0.5773502691896258 -0.5773502691896258 2.094395
                                children [
                                  SAHRV74_right_hip_panelMesh {
                                    color 1 0 0
                                  }
                                ]
                                name "right_hip_panel"
                                boundingObject Pose {
                                  translation 0 0 -0.0025
                                  rotation 0 1 0 0
                                  children [
                                    Box {
                                      size 0.058 0.07 0.007
                                    }
                                  ]
                                }
                                physics Physics {
                                  density -1
                                  mass 0.008452
                                  centerOfMass [
                                    0 0 -0.000328
                                  ]
                                  inertiaMatrix [
                                    3.2593e-06 2.2894e-06 5.5224e-06
                                    -9.9949e-16 -3.5382e-12 -1.5928e-21
                                  ]
                                }
                              }
                            ]
                            name "right_knee_bone_1"
                            boundingObject Pose {
                              translation 0.082439 -0.0015 2.2e-05
                              rotation 0 1 0 0
                              children [
                                Box {
                                  size 0.118878 0.003 0.044
                                }
                              ]
                            }
                            physics Physics {
                              density -1
                              mass 0.016935
                              centerOfMass [
                                0.077535 -0.0015 2.2e-05
                              ]
                              inertiaMatrix [
                                2.918984e-06 2.339099e-05 2.049741e-05
                                -2.362047e-21 1.217589e-21 -4.523817e-12
                              ]
                            }
                          }
                          Solid {
                            translation -2.2e-05 -0.128 0.058
                            rotation 0.5773506025225371 0.5773506025225371 0.5773496025232256 2.094396
                            children [
                              SAHRV74_right_knee_bone_2Mesh {
                              }
                            ]
                            name "right_knee_bone_2"
                            boundingObject Pose {
                              translation 0.082439 -0.0015 2.2e-05
                              rotation 0 1 0 0
                              children [
                                Box {
                                  size 0.118878 0.003 0.044
                                }
                              ]
                            }
                            physics Physics {
                              density -1
                              mass 0.016935
                              centerOfMass [
                                0.077535 -0.0015 2.2e-05
                              ]
                              inertiaMatrix [
                                2.918984e-06 2.339099e-05 2.049741e-05
                                -2.907779e-21 2.745991e-21 -4.523817e-12
                              ]
                            }
                          }
                        ]
                        name "right_knee_1"
                        boundingObject Pose {
                          translation 0 -0.12195 0.029
                          rotation 0 1 0 0
                          children [
                            Box {
                              size 0.049 0.0671 0.05
                            }
                          ]
                        }
                        physics Physics {
                          density -1
                          mass 0.185809
                          centerOfMass [
                            3e-06 -0.121892 0.02907
                          ]
                          inertiaMatrix [
                            7.705682e-05 4.823411e-05 6.693444e-05
                            3.06858e-09 -4.247805e-09 -1.841894e-06
                          ]
                        }
                      }
                    }
                    Solid {
                      translation -0.017 -0.0145 -0.016722
                      rotation 0.5773496025226483 -0.5773516025212714 -0.5773496025226483 2.094399
                      children [
                        SAHRV74_joint_block02Mesh {
                        }
                        Solid {
                          translation 0.0005 -0.0157 -0.002
                          rotation -0.5773496025226482 0.5773496025226482 0.5773516025212713 2.094399
                          children [
                            SAHRV74_dubel02Mesh {
                            }
                          ]
                          name "dubel02"
                          boundingObject Pose {
                            translation 0.015 -0.00305 -0.0155
                            rotation 0 1 0 0
                            children [
                              Box {
                                size 0.0402 0.0651 0.049
                              }
                            ]
                          }
                          physics Physics {
                            density -1
                            mass 0.159507
                            centerOfMass [
                              0.015004 -0.000778 -0.016589
                            ]
                            inertiaMatrix [
                              7.602558e-05 4.229576e-05 6.034857e-05
                              -3.06858e-09 4.247805e-09 -1.841894e-06
                            ]
                          }
                        }
                      ]
                      name "joint_block02"
                      boundingObject Pose {
                        translation 0.018 -0.00685 -0.017
                        rotation 0 1 0 0
                        children [
                          Box {
                            size 0.036 0.0177 0.039
                          }
                        ]
                      }
                      physics Physics {
                        density -1
                        mass 0.014404
                        centerOfMass [
                          0.019194 -0.007194 -0.016997
                        ]
                        inertiaMatrix [
                          2.951288e-06 4.145151e-06 1.362015e-06
                          -8.654079e-09 1.34958e-10 1.370111e-10
                        ]
                      }
                    }
                  ]
                  name "mx106_block_mir_1"
                  boundingObject Pose {
                    translation 0 -0.01805 0.005278
                    rotation 0 1 0 0
                    children [
                      Box {
                        size 0.052 0.0651 0.0508
                      }
                    ]
                  }
                  physics Physics {
                    density -1
                    mass 0.176516
                    centerOfMass [
                      7.4e-05 -0.014304 0.001878
                    ]
                    inertiaMatrix [
                      6.169158e-05 4.424123e-05 7.884576e-05
                      1.841894e-06 -4.239819e-09 -2.74733e-08
                    ]
                  }
                }
              }
            ]
            name "u_block_1"
            boundingObject Pose {
              translation 0.004709 0 0.008
              rotation 0 1 0 0
              children [
                Box {
                  size 0.056418 0.03 0.006
                }
              ]
            }
            physics Physics {
              density -1
              mass 0.01751
              centerOfMass [
                0.004375 0 0.007365
              ]
              inertiaMatrix [
                3.135657e-06 4.771178e-06 7.793656e-06
                -1.574594e-12 -9.785051e-09 7.609569e-14
              ]
            }
          }
        }
        DEF left_shoulder_pitch HingeJoint {
          jointParameters HingeJointParameters {
            position -1.0237675826819931e-07
            axis 1 -4e-06 -4e-06
            anchor 0.12366 -0.006258 0.155
            dampingConstant 1.23
            staticFriction 2.55
          }
          device [
            RotationalMotor {
              name "left_shoulder_pitch"
              maxVelocity 5.76
            }
            PositionSensor {
              name "left_shoulder_pitch_sensor"
              resolution 0.0015
            }
          ]
          endPoint Solid {
            translation 0.12366 -0.006258 0.155
            rotation -0.577349622334739 0.5773515628974979 -0.5773496223344663 2.0943990594356543
            children [
              SAHRV74_u_shoulder_1Mesh {
              }
              DEF left_shoulder_roll HingeJoint {
                jointParameters HingeJointParameters {
                  position -5.275521114391911e-08
                  axis 1 0 -2e-06
                  anchor 0.01035 0.03 0.0355
                  dampingConstant 0.65
                  staticFriction 1.73
                }
                device [
                  RotationalMotor {
                    name "left_shoulder_roll"
                    maxVelocity 8.17
                    maxTorque 7.3
                  }
                  PositionSensor {
                    name "left_shoulder_roll_sensor"
                    resolution 0.0015
                  }
                ]
                endPoint Solid {
                  translation 0.01035 0.03 0.0355
                  rotation -0.7071062811861704 1.899470711745136e-08 0.7071072811865708 3.1415930379895127
                  children [
                    SAHRV74_left_humerus_1Mesh {
                    }
                    DEF left_elbow HingeJoint {
                      jointParameters HingeJointParameters {
                        position -1.650961772925127e-07
                        axis -1 0 2e-06
                        anchor -0.0255 -0.1145 0.00995
                        dampingConstant 0.65
                        staticFriction 1.73
                      }
                      device [
                        RotationalMotor {
                          name "left_elbow"
                          maxVelocity 8.17
                          maxTorque 7.3
                        }
                        PositionSensor {
                          name "left_elbow_sensor"
                          resolution 0.0015
                        }
                      ]
                      endPoint Solid {
                        translation -0.0255 -0.1145 0.00995
                        rotation 0.7071072811865603 -5.8370388722273614e-08 0.7071062811861788 3.1415931167404754
                        children [
                          SAHRV74_left_radius_1Mesh {
                          }
                          Solid {
                            translation 0.026 0.1589 0.0395
                            rotation 0 0 1 3.141593
                            children [
                              SAHRV74_left_radius_1_1_radius_plateMesh {
                              }
                              Solid {
                                translation 0 0 -0.014
                                rotation 0 1 0 0
                                children [
                                  SAHRV74_left_boxing_gloveMesh {
                                  }
                                  Solid {
                                    translation 0 -0.035 0
                                    rotation 0 1 0 0
                                    name "left_hand_end [hand]"
                                    boundingObject Pose {
                                      children [
                                        Sphere {
                                          radius 0.002
                                        }
                                      ]
                                    }
                                    physics Physics {
                                      density -1
                                      mass 0.001
                                    }
                                  }
                                ]
                                name "left_boxing_glove"
                                boundingObject Group {
                                  children [
                                    Pose {
                                      translation 0 0.07 0
                                      rotation 0 0 -1 1.570796
                                      children [
                                        Box {
                                          size 0.07 0.03 0.028
                                        }
                                      ]
                                    }
                                    Pose {
                                      rotation -1 0 0 3.2646808475564034e-07
                                      children [
                                        Cylinder {
                                          height 0.03
                                          radius 0.035
                                        }
                                      ]
                                    }
                                  ]
                                }
                                physics Physics {
                                  density -1
                                  mass 0.036095
                                  centerOfMass [
                                    -8.5e-05 0.035047 0
                                  ]
                                  inertiaMatrix [
                                    4.953461e-05 1.028778e-05 5.516469e-05
                                    1.098263e-07 -8.810928e-12 2.738622e-13
                                  ]
                                }
                              }
                            ]
                            name "left_radius_1_1_radius_plate [arm]"
                            boundingObject Pose {
                              translation -0.0115 0.1109 -0.014
                              rotation 0 1 0 0
                              children [
                                Box {
                                  size 0.003 0.124 0.028
                                }
                              ]
                            }
                            physics Physics {
                              density -1
                              mass 0.01274
                              centerOfMass [
                                -0.0115 0.113902 -0.014
                              ]
                              inertiaMatrix [
                                1.680597e-05 9.732133e-07 1.585187e-05
                                8.488275e-21 1.491642e-12 6.318772e-19
                              ]
                            }
                          }
                          Solid {
                            translation 0.036 0 0.002
                            rotation -0.5773496025232256 -0.5773506025225371 0.5773506025225371 4.188789
                            children [
                              SAHRV74_left_radius_bone1Mesh {
                              }
                            ]
                            name "left_radius_bone1 [arm]"
                            boundingObject Pose {
                              translation -0.023525 -0.0195 0
                              rotation 0 1 0 0
                              children [
                                Box {
                                  size 0.05095 0.039 0.028
                                }
                              ]
                            }
                            physics Physics {
                              density -1
                              mass 0.004365
                              centerOfMass [
                                -0.047992 -0.018809 0
                              ]
                              inertiaMatrix [
                                8.704731e-07 3.405717e-07 5.327952e-07
                                -6.426069e-10 -2.364855e-24 2.012585e-22
                              ]
                            }
                          }
                          Solid {
                            translation 0.036 0 0.049
                            rotation -0.5773496025232256 -0.5773506025225371 0.5773506025225371 4.188789
                            children [
                              SAHRV74_left_radius_bone2Mesh {
                              }
                            ]
                            name "left_radius_bone2 [arm]"
                            boundingObject Pose {
                              translation 0.023525 -0.0195 0
                              rotation 0 1 0 0
                              children [
                                Box {
                                  size 0.05095 0.039 0.028
                                }
                              ]
                            }
                            physics Physics {
                              density -1
                              mass 0.004365
                              centerOfMass [
                                0.047992 -0.018809 0
                              ]
                              inertiaMatrix [
                                8.704731e-07 3.405717e-07 5.327952e-07
                                6.426069e-10 1.086059e-23 1.901281e-22
                              ]
                            }
                          }
                        ]
                        name "left_radius_1 [arm]"
                        boundingObject Pose {
                          translation 0.028 0 0.0255
                          rotation 0 1 0 0
                          children [
                            Box {
                              size 0.016 0.033 0.0509
                            }
                          ]
                        }
                        physics Physics {
                          density -1
                          mass 0.008755
                          centerOfMass [
                            0.034048 0 0.0255
                          ]
                          inertiaMatrix [
                            2.837158e-06 1.671192e-06 1.221285e-06
                            -5.970066e-23 -2.526251e-12 -8.476985e-23
                          ]
                        }
                      }
                    }
                    Solid {
                      translation -0.021 -0.0425 0.00995
                      rotation 0 -1 0 4.712389
                      children [
                        SAHRV74_left_humerus_panelMesh {
                          color 1 0 0
                        }
                      ]
                      name "left_humerus_panel [arm]"
                      boundingObject Pose {
                        translation 0 0 0.003
                        rotation 0 1 0 0
                        children [
                          Box {
                            size 0.044 0.11 0.008
                          }
                        ]
                      }
                      physics Physics {
                        density -1
                        mass 0.008741
                        centerOfMass [
                          0 -0.001326 8.8e-05
                        ]
                        inertiaMatrix [
                          8.2273e-06 1.5648e-06 9.7699e-06
                          4.411e-21 2.4145e-22 3.3315e-08
                        ]
                      }
                    }
                  ]
                  name "left_humerus_1 [arm]"
                  boundingObject Pose {
                    translation 0.00039 -0.05725 0.01074
                    rotation 0 1 0 0
                    children [
                      Box {
                        size 0.04778 0.1425 0.04778
                      }
                    ]
                  }
                  physics Physics {
                    density -1
                    mass 0.313976
                    centerOfMass [
                      0.000149 -0.05725 0.010282
                    ]
                    inertiaMatrix [
                      0.0001134802 7.736216e-05 0.0001134802
                      -1.641487e-06 -3.698787e-11 1.641487e-06
                    ]
                  }
                }
              }
              Solid {
                translation 0.0235 0 0.0005
                rotation 0.5773502691896258 -0.5773502691896258 -0.5773502691896258 2.094395
                children [
                  SAHRV74_u_shoulder_1_bone_frontMesh {
                  }
                ]
                name "u_shoulder_1_bone_front [arm]"
                boundingObject Pose {
                  translation -0.0105 0.02675 -0.0015
                  rotation 0 1 0 0
                  children [
                    Box {
                      size 0.051 0.0445 0.003
                    }
                  ]
                }
                physics Physics {
                  density -1
                  mass 0.005838
                  centerOfMass [
                    -0.009078 0.026395 -0.0015
                  ]
                  inertiaMatrix [
                    9.504486e-07 1.089626e-06 2.031318e-06
                    4.840052e-07 -7.566924e-13 1.472239e-12
                  ]
                }
              }
              Solid {
                translation -0.0265 0 0.0005
                rotation 0.5773502691896258 -0.5773502691896258 -0.5773502691896258 2.094395
                children [
                  SAHRV74_u_shoulder_1_bone_backMesh {
                  }
                ]
                name "u_shoulder_1_bone_back [arm]"
                boundingObject Pose {
                  translation -0.0105 0.02675 -0.0015
                  rotation 0 1 0 0
                  children [
                    Box {
                      size 0.051 0.0445 0.003
                    }
                  ]
                }
                physics Physics {
                  density -1
                  mass 0.005838
                  centerOfMass [
                    -0.009078 0.026395 -0.0015
                  ]
                  inertiaMatrix [
                    9.504486e-07 1.089626e-06 2.031318e-06
                    4.840052e-07 -7.566924e-13 1.472239e-12
                  ]
                }
              }
            ]
            name "u_shoulder_1 [arm]"
            boundingObject Pose {
              translation 0 0 0.0055
              rotation 0 1 0 0
              children [
                Box {
                  size 0.053 0.047 0.011
                }
              ]
            }
            physics Physics {
              density -1
              mass 0.050475
              centerOfMass [
                0 0 0.003446
              ]
              inertiaMatrix [
                7.624516e-06 9.937798e-06 1.741304e-05
                2.86185e-14 1.529543e-11 -1.304723e-14
              ]
            }
          }
        }
        DEF right_shoulder_pitch HingeJoint {
          jointParameters HingeJointParameters {
            position 1.6999617345380288e-07
            axis 1 4e-06 -4e-06
            anchor -0.022341 -0.006258 0.155
            dampingConstant 1.23
            staticFriction 2.55
          }
          device [
            RotationalMotor {
              name "right_shoulder_pitch"
              maxVelocity 5.76
            }
            PositionSensor {
              name "right_shoulder_pitch_sensor"
              resolution 0.0015
            }
          ]
          endPoint Solid {
            translation -0.022341 -0.006258 0.155
            rotation 0.5773496349624965 0.5773515376422409 0.5773496349620499 2.094399097318555
            children [
              SAHRV74_u_shoulder_2Mesh {
              }
              DEF right_shoulder_roll HingeJoint {
                jointParameters HingeJointParameters {
                  position 7.39609355394587e-08
                  axis -1 0 2e-06
                  anchor 0.009113 -0.03 -0.0355
                  dampingConstant 0.65
                  staticFriction 1.73
                }
                device [
                  RotationalMotor {
                    name "right_shoulder_roll"
                    maxVelocity 8.17
                    maxTorque 7.3
                  }
                  PositionSensor {
                    name "right_shoulder_roll_sensor"
                    resolution 0.0015
                  }
                ]
                endPoint Solid {
                  translation 0.009113 -0.03 -0.0355
                  rotation -3.703747216509791e-08 -0.9999999999999988 3.703757117398898e-08 1.5707949999999724
                  children [
                    SAHRV74_right_humerus_1Mesh {
                    }
                    DEF right_elbow HingeJoint {
                      jointParameters HingeJointParameters {
                        position -1.5990305184343843e-07
                        axis 1 0 2e-06
                        anchor -0.014021 -0.1145 0.009113
                        dampingConstant 0.65
                        staticFriction 1.73
                      }
                      device [
                        RotationalMotor {
                          name "right_elbow"
                          maxVelocity 8.17
                          maxTorque 7.3
                        }
                        PositionSensor {
                          name "right_elbow_sensor"
                          resolution 0.0015
                        }
                      ]
                      endPoint Solid {
                        translation -0.014021 -0.1145 0.009113
                        rotation -0.7071072811865609 5.65343392381662e-08 0.7071062811861784 3.141593113068386
                        children [
                          SAHRV74_right_radius_1Mesh {
                          }
                          Solid {
                            translation 0.026 0.159 -0.028021
                            rotation 0 0 -1 1.570796
                            children [
                              SAHRV74_right_radius_1_0_radius_plateMesh {
                              }
                              Solid {
                                translation 0 0 0.014
                                rotation 0 0 -1 1.570796
                                children [
                                  SAHRV74_right_boxing_gloveMesh {
                                  }
                                  Solid {
                                    translation 0 -0.035 0
                                    rotation 0 1 0 0
                                    name "right_hand_end [hand]"
                                    boundingObject Pose {
                                      children [
                                        Sphere {
                                          radius 0.002
                                        }
                                      ]
                                    }
                                    physics Physics {
                                      density -1
                                      mass 0.001
                                    }
                                  }
                                ]
                                name "right_boxing_glove"
                                boundingObject Group {
                                  children [
                                    Pose {
                                      translation 0 0.07 0
                                      rotation 0 0 -1 1.570796
                                      children [
                                        Box {
                                          size 0.07 0.03 0.028
                                        }
                                      ]
                                    }
                                    Pose {
                                      rotation -1 0 0 3.2646808475564034e-07
                                      children [
                                        Cylinder {
                                          height 0.03
                                          radius 0.035
                                        }
                                      ]
                                    }
                                  ]
                                }
                                physics Physics {
                                  density -1
                                  mass 0.036095
                                  centerOfMass [
                                    -8.5e-05 0.035047 0
                                  ]
                                  inertiaMatrix [
                                    4.953461e-05 1.028778e-05 5.516469e-05
                                    1.098263e-07 -8.810928e-12 2.738622e-13
                                  ]
                                }
                              }
                            ]
                            name "right_radius_1_0_radius_plate [arm]"
                            boundingObject Pose {
                              translation 0.111 0.0115 0.014
                              rotation 0 1 0 0
                              children [
                                Box {
                                  size 0.124 0.003 0.028
                                }
                              ]
                            }
                            physics Physics {
                              density -1
                              mass 0.01274
                              centerOfMass [
                                0.114002 0.0115 0.014
                              ]
                              inertiaMatrix [
                                9.732133e-07 1.680597e-05 1.585187e-05
                                -3.267791e-21 -6.365388e-19 -1.491642e-12
                              ]
                            }
                          }
                          Solid {
                            translation 0.036 0 0.009479
                            rotation 0.5773502691896258 0.5773502691896258 -0.5773502691896258 2.094395
                            children [
                              SAHRV74_right_radius_bone1Mesh {
                              }
                            ]
                            name "right_radius_bone1 [arm]"
                            boundingObject Pose {
                              translation 0.023475 -0.0195 0
                              rotation 0 1 0 0
                              children [
                                Box {
                                  size 0.05095 0.039 0.028
                                }
                              ]
                            }
                            physics Physics {
                              density -1
                              mass 0.004365
                              centerOfMass [
                                -0.000992 -0.018809 0
                              ]
                              inertiaMatrix [
                                8.704731e-07 3.405717e-07 5.327952e-07
                                -6.426069e-10 8.196046e-24 3.557327e-23
                              ]
                            }
                          }
                          Solid {
                            translation 0.036 0 -0.037521
                            rotation 0.5773502691896258 0.5773502691896258 -0.5773502691896258 2.094395
                            children [
                              SAHRV74_right_radius_bone2Mesh {
                              }
                            ]
                            name "right_radius_bone2 [arm]"
                            boundingObject Pose {
                              translation -0.023475 -0.0195 0
                              rotation 0 1 0 0
                              children [
                                Box {
                                  size 0.05095 0.039 0.028
                                }
                              ]
                            }
                            physics Physics {
                              density -1
                              mass 0.004365
                              centerOfMass [
                                0.000992 -0.018809 0
                              ]
                              inertiaMatrix [
                                8.704731e-07 3.405717e-07 5.327952e-07
                                6.426069e-10 2.426651e-24 6.254089e-23
                              ]
                            }
                          }
                        ]
                        name "right_radius_1 [arm]"
                        boundingObject Pose {
                          translation 0.028 0 -0.014021
                          rotation 0 1 0 0
                          children [
                            Box {
                              size 0.016 0.033 0.0509
                            }
                          ]
                        }
                        physics Physics {
                          density -1
                          mass 0.008755
                          centerOfMass [
                            0.034048 0 -0.014021
                          ]
                          inertiaMatrix [
                            2.837158e-06 1.671192e-06 1.221285e-06
                            3.979284e-22 -3.915388e-22 -4.846271e-22
                          ]
                        }
                      }
                    }
                    Solid {
                      translation -0.021 -0.0425 0.009113
                      rotation 0 1 0 1.570796
                      children [
                        SAHRV74_right_humerus_panelMesh {
                          color 1 0 0
                        }
                      ]
                      name "right_humerus_panel [arm]"
                      boundingObject Pose {
                        translation 0 0 0.003
                        rotation 0 1 0 0
                        children [
                          Box {
                            size 0.044 0.11 0.008
                          }
                        ]
                      }
                      physics Physics {
                        density -1
                        mass 0.008741
                        centerOfMass [
                          0 -0.001326 8.8e-05
                        ]
                        inertiaMatrix [
                          8.2273e-06 1.5648e-06 9.7699e-06
                          -5.2085e-14 -2.4117e-12 3.3315e-08
                        ]
                      }
                    }
                  ]
                  name "right_humerus_1 [arm]"
                  boundingObject Pose {
                    translation 0.00039 -0.05725 0.008723
                    rotation 0 1 0 0
                    children [
                      Box {
                        size 0.04778 0.1425 0.04778
                      }
                    ]
                  }
                  physics Physics {
                    density -1
                    mass 0.313976
                    centerOfMass [
                      0.000149 -0.05725 0.008965
                    ]
                    inertiaMatrix [
                      0.0001134802 7.736216e-05 0.0001134802
                      -1.641434e-06 -3.698787e-11 -1.641439e-06
                    ]
                  }
                }
              }
              Solid {
                translation -0.0265 0 -0.0005
                rotation -0.5773502691896258 -0.5773502691896258 0.5773502691896258 2.094395
                children [
                  SAHRV74_u_shoulder_2_bone_frontMesh {
                  }
                ]
                name "u_shoulder_2_bone_front [arm]"
                boundingObject Pose {
                  translation -0.0105 0.02675 -0.0015
                  rotation 0 1 0 0
                  children [
                    Box {
                      size 0.051 0.0445 0.003
                    }
                  ]
                }
                physics Physics {
                  density -1
                  mass 0.005838
                  centerOfMass [
                    -0.009078 0.026395 -0.0015
                  ]
                  inertiaMatrix [
                    9.504486e-07 1.089626e-06 2.031318e-06
                    4.840052e-07 8.624285e-18 -1.677877e-17
                  ]
                }
              }
              Solid {
                translation 0.0235 0 -0.0005
                rotation -0.5773502691896258 -0.5773502691896258 0.5773502691896258 2.094395
                children [
                  SAHRV74_u_shoulder_2_bone_backMesh {
                  }
                ]
                name "u_shoulder_2_bone_back [arm]"
                boundingObject Pose {
                  translation -0.0105 0.02675 -0.0015
                  rotation 0 1 0 0
                  children [
                    Box {
                      size 0.051 0.0445 0.003
                    }
                  ]
                }
                physics Physics {
                  density -1
                  mass 0.005838
                  centerOfMass [
                    -0.009078 0.026395 -0.0015
                  ]
                  inertiaMatrix [
                    9.504486e-07 1.089626e-06 2.031318e-06
                    4.840052e-07 -2.574725e-17 5.009502e-17
                  ]
                }
              }
            ]
            name "u_shoulder_2 [arm]"
            boundingObject Pose {
              translation 0 0 -0.0055
              rotation 0 1 0 0
              children [
                Box {
                  size 0.053 0.047 0.011
                }
              ]
            }
            physics Physics {
              density -1
              mass 0.050475
              centerOfMass [
                0 0 -0.003446
              ]
              inertiaMatrix [
                7.624516e-06 9.937798e-06 1.741304e-05
                -2.861851e-14 7.922495e-15 -1.304719e-14
              ]
            }
          }
        }
        Solid {
          translation 0.050658 -0.011338 0.1842
          rotation 0 0 -1 1.5708
          children [
            SAHRV74_head_baseMesh {
            }
          ]
          name "head_base"
        }
        Solid {
          translation 0.050517 0.014637 -0.0489
          rotation 0 0 -1 1.5708
          children [
            SAHRV74_trunkMesh {
            }
          ]
          name "trunk"
        }
        Solid {
          translation 0.050658 -0.024258 0.141
          rotation 0 0 1 3.1416
          children [
            SAHRV74_Front_dempherMesh {
            }
          ]
          name "Front_dempher"
          boundingObject Pose {
            translation 0 0.028425 0
            rotation 0 1 0 0
            children [
              Box {
                size 0.133516 0.063849 0.02
              }
            ]
          }
          physics Physics {
            density -1
            mass 0.030851
            centerOfMass [
              0 0.023804 -5.5e-05
            ]
            inertiaMatrix [
              1.239465e-05 4.266907e-05 5.317651e-05
              6.545695e-15 1.988453e-14 -3.388747e-08
            ]
          }
        }
        Solid {
          translation 0.11966 0.095622 0.21588
          rotation 0.017494997868357107 -0.9996938781943062 -0.017494997868357107 1.571103
          children [
            SAHRV74_HandleMesh {
            }
          ]
          name "Handle"
          boundingObject Pose {
            translation -0.027821 -0.01593 0.069
            rotation 0 1 0 0
            children [
              Box {
                size 0.093842 0.070059 0.144
              }
            ]
          }
          physics Physics {
            density -1
            mass 0.035214
            centerOfMass [
              -0.011016 -0.006641 0.069
            ]
            inertiaMatrix [
              6.074648e-05 6.249415e-05 1.448903e-05
              -4.632062e-06 9.771227e-12 -7.525873e-11
            ]
          }
        }
        Solid {
          translation 0.050658 0.013186 0.123
          rotation -0.5773496025226483 -0.5773516025212714 0.5773496025226483 2.094399
          children [
            SAHRV74_DXL_BoardMesh {
            }
            Accelerometer {
              rotation 1 0 0 1.5706
              lookupTable [
                -78.48 0 0
                78.48 65535 0
              ]
            }
            Gyro {
              rotation 1 0 0 1.5706
              lookupTable [
                -17.453333333333 0 0
                17.453333333333 65535 0
              ]
            }
            InertialUnit {
              rotation 1 0 0 1.5706
              name "imu"
            }
          ]
          name "DXL_Board"
          boundingObject Pose {
            translation 0 0.0063 0
            rotation 0 1 0 0
            children [
              Box {
                size 0.052 0.0226 0.072351
              }
            ]
          }
          physics Physics {
            density -1
            mass 0.05901
            centerOfMass [
              -0.001639 0.007699 0.001748
            ]
            inertiaMatrix [
              2.074849e-05 3.539271e-05 1.791081e-05
              4.951005e-07 -8.48836e-07 -2.058427e-07
            ]
          }
        }
        Solid {
          translation -0.014341 0.063742 0
          rotation -3.000001192953712e-06 0.707108281182371 0.7071052811811781 3.141598
          children [
            SAHRV74_cover_batteryMesh {
              color 1 0 0
            }
          ]
          name "cover_battery"
          boundingObject Pose {
            translation -0.065 0.0251 0.013879
            rotation 0 1 0 0
            children [
              Box {
                size 0.158 0.065 0.036243
              }
            ]
          }
          physics Physics {
            density -1
            mass 0.037304
            centerOfMass [
              -0.065 0.026664 0.020215
            ]
            inertiaMatrix [
              1.6845e-05 7.191e-05 8.5267e-05
              4.5358e-11 2.673e-10 7.9446e-07
            ]
          }
        }
        Solid {
          translation 0.050658 -0.033258 0.0435
          rotation 0 0 1 3.1416
          children [
            SAHRV74_front_panelMesh {
              color 1 0 0
            }
          ]
          name "front_panel"
          boundingObject Pose {
            translation 0 -0.002511 0.04
            rotation 0 1 0 0
            children [
              Box {
                size 0.1476 0.012422 0.08
              }
            ]
          }
          physics Physics {
            density -1
            mass 0.031834
            centerOfMass [
              0 -0.001853 0.047157
            ]
            inertiaMatrix [
              1.6809e-05 6.6362e-05 4.9762e-05
              -8.8116e-13 -5.8624e-12 8.6952e-08
            ]
          }
        }
        Solid {
          translation 0.11464 0.017753 0.043
          rotation 0 0 1 3.1195
          children [
            SAHRV74_left_panelMesh {
              color 1 0 0
            }
          ]
          name "left_panel"
          boundingObject Pose {
            translation -0.003939 0 0.04
            rotation 0 1 0 0
            children [
              Box {
                size 0.015322 0.1136 0.08
              }
            ]
          }
          physics Physics {
            density -1
            mass 0.022701
            centerOfMass [
              -0.003011 0.004899 0.035218
            ]
            inertiaMatrix [
              3.0975e-05 1.0418e-05 2.0751e-05
              -2.2801e-07 4.462e-08 1.5004e-06
            ]
          }
        }
        Solid {
          translation -0.013326 0.017731 0.043
          rotation 0 0 1 0.021405
          children [
            SAHRV74_right_panelMesh {
              color 1 0 0
            }
          ]
          name "right_panel"
          boundingObject Pose {
            translation -0.001039 0 0.04
            rotation 0 1 0 0
            children [
              Box {
                size 0.009522 0.1136 0.08
              }
            ]
          }
          physics Physics {
            density -1
            mass 0.022701
            centerOfMass [
              -0.003011 0.004899 0.035218
            ]
            inertiaMatrix [
              3.0975e-05 1.0418e-05 2.0751e-05
              -2.2801e-07 4.462e-08 1.5004e-06
            ]
          }
        }
        Solid {
          translation 0.050513 -0.033271 0.049754
          rotation 0.9980992377178227 0.04357701037875958 0.04357701037875958 1.572703
          children [
            SAHRV74_num_01Mesh {
            }
          ]
          name "num_01"
          boundingObject Pose {
            translation 0.016667 0.024746 0.0005
            rotation 0 1 0 0
            children [
              Box {
                size 0.017949 0.05 0.001
              }
            ]
          }
          physics Physics {
            density -1
            mass 0.000556
            centerOfMass [
              0.020778 0.027022 0.0005
            ]
            inertiaMatrix [
              1.080986e-07 9.433419e-09 1.174393e-07
              9.079101e-09 3.308722e-24 -2.688337e-24
            ]
          }
        }
        Solid {
          translation 0.039319 0.094191 0.002854
          rotation 0.09851402453117733 -0.7036681752218413 -0.7036661752213434 2.945199
          children [
            SAHRV74_number_01Mesh {
            }
          ]
          name "number_01"
          boundingObject Pose {
            translation 0.016667 0.024746 0.0005
            rotation 0 1 0 0
            children [
              Box {
                size 0.017949 0.05 0.001
              }
            ]
          }
          physics Physics {
            density -1
            mass 0.000556
            centerOfMass [
              0.020778 0.027022 0.0005
            ]
            inertiaMatrix [
              1.080986e-07 9.433419e-09 1.174393e-07
              9.079101e-09 0 -1.943874e-23
            ]
          }
        }
      ]
      name "trunk_1"
      boundingObject Group {
        children [
          Pose {
            translation 0.050658 0.033853 0.11
            rotation 0 1 0 0
            children [
              Box {
                size 0.1464 0.140223 0.14
              }
            ]
          }
          Pose {
            translation 0.050658 0.055 0.0185
            rotation 0 1 0 0
            children [
              Box {
                size 0.1464 0.05 0.045
              }
            ]
          }
        ]
      }
      physics Physics {
        density -1
        mass 2.244518
        centerOfMass [
          0.051018 0.031673 0.076972
        ]
        inertiaMatrix [
          0.00122137 0.002692811 0.002548973
          -7.319495e-07 1.316733e-06 4.78746e-06
        ]
      }
    }
  ]
  name "red player 1"
  model "SAHR"
  boundingObject Pose {
    rotation 0 1 0 0
    children [
      Box {
        size 0.001 0.001 0.001
      }
    ]
  }
  physics Physics {
    density -1
    mass 0.001
  }
  controller "head_controller"
  supervisor TRUE
  selfCollision TRUE
}
